Workbook

Sheet Когортний LTV
A1: Когортний аналіз LTV — Superstore
A2: Когорта — квартал першої покупки клієнта. LTV — кумулятивний дохід (Sales) когорти, поділений на кількість клієнтів у когорті, $ на клієнта.
A4: 1. Дохід когорти за роками замовлення, $ | I4: Висновки
A5: Когорта | B5: Клієнтів | C5: 2020 | D5: 2021 | E5: 2022 | F5: 2023 | G5: Разом
A6: 2020 Q1 | B6: =COUNTIF(Customers!$D$2:$D$805,$A6) | C6: =SUMIFS(Orders!$R$2:$R$10195,Orders!$W$2:$W$10195,$A6,Orders!$X$2:$X$10195,C$5) | D6: =SUMIFS(Orders!$R$2:$R$10195,Orders!$W$2:$W$10195,$A6,Orders!$X$2:$X$10195,D$5) | E6: =SUMIFS(Orders!$R$2:$R$10195,Orders!$W$2:$W$10195,$A6,Orders!$X$2:$X$10195,E$5) | F6: =SUMIFS(Orders!$R$2:$R$10195,Orders!$W$2:$W$10195,$A6,Orders!$X$2:$X$10195,F$5) | G6: =SUM(C6:F6) | I6: Найцінніші — когорти першого року.
A7: 2020 Q2 | B7: =COUNTIF(Customers!$D$2:$D$805,$A7) | C7: =SUMIFS(Orders!$R$2:$R$10195,Orders!$W$2:$W$10195,$A7,Orders!$X$2:$X$10195,C$5) | D7: =SUMIFS(Orders!$R$2:$R$10195,Orders!$W$2:$W$10195,$A7,Orders!$X$2:$X$10195,D$5) | E7: =SUMIFS(Orders!$R$2:$R$10195,Orders!$W$2:$W$10195,$A7,Orders!$X$2:$X$10195,E$5) | F7: =SUMIFS(Orders!$R$2:$R$10195,Orders!$W$2:$W$10195,$A7,Orders!$X$2:$X$10195,F$5) | G7: =SUM(C7:F7) | I7: Когорта 2020 Q1 має найвищий LTV: $3,429 на клієнта на кінець 2023 року. Усі когорти 2020 року накопичили $2,906–$3,429 за чотири роки, і серед них що раніше долучився клієнт, то вищий його LTV.
A8: 2020 Q3 | B8: =COUNTIF(Customers!$D$2:$D$805,$A8) | C8: =SUMIFS(Orders!$R$2:$R$10195,Orders!$W$2:$W$10195,$A8,Orders!$X$2:$X$10195,C$5) | D8: =SUMIFS(Orders!$R$2:$R$10195,Orders!$W$2:$W$10195,$A8,Orders!$X$2:$X$10195,D$5) | E8: =SUMIFS(Orders!$R$2:$R$10195,Orders!$W$2:$W$10195,$A8,Orders!$X$2:$X$10195,E$5) | F8: =SUMIFS(Orders!$R$2:$R$10195,Orders!$W$2:$W$10195,$A8,Orders!$X$2:$X$10195,F$5) | G8: =SUM(C8:F8)
A9: 2020 Q4 | B9: =COUNTIF(Customers!$D$2:$D$805,$A9) | C9: =SUMIFS(Orders!$R$2:$R$10195,Orders!$W$2:$W$10195,$A9,Orders!$X$2:$X$10195,C$5) | D9: =SUMIFS(Orders!$R$2:$R$10195,Orders!$W$2:$W$10195,$A9,Orders!$X$2:$X$10195,D$5) | E9: =SUMIFS(Orders!$R$2:$R$10195,Orders!$W$2:$W$10195,$A9,Orders!$X$2:$X$10195,E$5) | F9: =SUMIFS(Orders!$R$2:$R$10195,Orders!$W$2:$W$10195,$A9,Orders!$X$2:$X$10195,F$5) | G9: =SUM(C9:F9)
A10: 2021 Q1 | B10: =COUNTIF(Customers!$D$2:$D$805,$A10) | C10: =SUMIFS(Orders!$R$2:$R$10195,Orders!$W$2:$W$10195,$A10,Orders!$X$2:$X$10195,C$5) | D10: =SUMIFS(Orders!$R$2:$R$10195,Orders!$W$2:$W$10195,$A10,Orders!$X$2:$X$10195,D$5) | E10: =SUMIFS(Orders!$R$2:$R$10195,Orders!$W$2:$W$10195,$A10,Orders!$X$2:$X$10195,E$5) | F10: =SUMIFS(Orders!$R$2:$R$10195,Orders!$W$2:$W$10195,$A10,Orders!$X$2:$X$10195,F$5) | G10: =SUM(C10:F10)
A11: 2021 Q2 | B11: =COUNTIF(Customers!$D$2:$D$805,$A11) | C11: =SUMIFS(Orders!$R$2:$R$10195,Orders!$W$2:$W$10195,$A11,Orders!$X$2:$X$10195,C$5) | D11: =SUMIFS(Orders!$R$2:$R$10195,Orders!$W$2:$W$10195,$A11,Orders!$X$2:$X$10195,D$5) | E11: =SUMIFS(Orders!$R$2:$R$10195,Orders!$W$2:$W$10195,$A11,Orders!$X$2:$X$10195,E$5) | F11: =SUMIFS(Orders!$R$2:$R$10195,Orders!$W$2:$W$10195,$A11,Orders!$X$2:$X$10195,F$5) | G11: =SUM(C11:F11) | I11: LTV не виходить на плато.
A12: 2021 Q3 | B12: =COUNTIF(Customers!$D$2:$D$805,$A12) | C12: =SUMIFS(Orders!$R$2:$R$10195,Orders!$W$2:$W$10195,$A12,Orders!$X$2:$X$10195,C$5) | D12: =SUMIFS(Orders!$R$2:$R$10195,Orders!$W$2:$W$10195,$A12,Orders!$X$2:$X$10195,D$5) | E12: =SUMIFS(Orders!$R$2:$R$10195,Orders!$W$2:$W$10195,$A12,Orders!$X$2:$X$10195,E$5) | F12: =SUMIFS(Orders!$R$2:$R$10195,Orders!$W$2:$W$10195,$A12,Orders!$X$2:$X$10195,F$5) | G12: =SUM(C12:F12) | I12: Клієнти купують повторно щороку: когорти 2020 року додають приблизно $600–1 000 на клієнта за рік, і приріст не згасає: у 2023 році він становив $820–$1,014. Утримання працює добре.
A13: 2021 Q4 | B13: =COUNTIF(Customers!$D$2:$D$805,$A13) | C13: =SUMIFS(Orders!$R$2:$R$10195,Orders!$W$2:$W$10195,$A13,Orders!$X$2:$X$10195,C$5) | D13: =SUMIFS(Orders!$R$2:$R$10195,Orders!$W$2:$W$10195,$A13,Orders!$X$2:$X$10195,D$5) | E13: =SUMIFS(Orders!$R$2:$R$10195,Orders!$W$2:$W$10195,$A13,Orders!$X$2:$X$10195,E$5) | F13: =SUMIFS(Orders!$R$2:$R$10195,Orders!$W$2:$W$10195,$A13,Orders!$X$2:$X$10195,F$5) | G13: =SUM(C13:F13)
A14: 2022 Q1 | B14: =COUNTIF(Customers!$D$2:$D$805,$A14) | C14: =SUMIFS(Orders!$R$2:$R$10195,Orders!$W$2:$W$10195,$A14,Orders!$X$2:$X$10195,C$5) | D14: =SUMIFS(Orders!$R$2:$R$10195,Orders!$W$2:$W$10195,$A14,Orders!$X$2:$X$10195,D$5) | E14: =SUMIFS(Orders!$R$2:$R$10195,Orders!$W$2:$W$10195,$A14,Orders!$X$2:$X$10195,E$5) | F14: =SUMIFS(Orders!$R$2:$R$10195,Orders!$W$2:$W$10195,$A14,Orders!$X$2:$X$10195,F$5) | G14: =SUM(C14:F14)
A15: 2022 Q2 | B15: =COUNTIF(Customers!$D$2:$D$805,$A15) | C15: =SUMIFS(Orders!$R$2:$R$10195,Orders!$W$2:$W$10195,$A15,Orders!$X$2:$X$10195,C$5) | D15: =SUMIFS(Orders!$R$2:$R$10195,Orders!$W$2:$W$10195,$A15,Orders!$X$2:$X$10195,D$5) | E15: =SUMIFS(Orders!$R$2:$R$10195,Orders!$W$2:$W$10195,$A15,Orders!$X$2:$X$10195,E$5) | F15: =SUMIFS(Orders!$R$2:$R$10195,Orders!$W$2:$W$10195,$A15,Orders!$X$2:$X$10195,F$5) | G15: =SUM(C15:F15)
A16: 2022 Q3 | B16: =COUNTIF(Customers!$D$2:$D$805,$A16) | C16: =SUMIFS(Orders!$R$2:$R$10195,Orders!$W$2:$W$10195,$A16,Orders!$X$2:$X$10195,C$5) | D16: =SUMIFS(Orders!$R$2:$R$10195,Orders!$W$2:$W$10195,$A16,Orders!$X$2:$X$10195,D$5) | E16: =SUMIFS(Orders!$R$2:$R$10195,Orders!$W$2:$W$10195,$A16,Orders!$X$2:$X$10195,E$5) | F16: =SUMIFS(Orders!$R$2:$R$10195,Orders!$W$2:$W$10195,$A16,Orders!$X$2:$X$10195,F$5) | G16: =SUM(C16:F16) | I16: Залучення нових клієнтів різко падає.
A17: 2022 Q4 | B17: =COUNTIF(Customers!$D$2:$D$805,$A17) | C17: =SUMIFS(Orders!$R$2:$R$10195,Orders!$W$2:$W$10195,$A17,Orders!$X$2:$X$10195,C$5) | D17: =SUMIFS(Orders!$R$2:$R$10195,Orders!$W$2:$W$10195,$A17,Orders!$X$2:$X$10195,D$5) | E17: =SUMIFS(Orders!$R$2:$R$10195,Orders!$W$2:$W$10195,$A17,Orders!$X$2:$X$10195,E$5) | F17: =SUMIFS(Orders!$R$2:$R$10195,Orders!$W$2:$W$10195,$A17,Orders!$X$2:$X$10195,F$5) | G17: =SUM(C17:F17) | I17: Нових клієнтів за роками: 2020 — 605, 2021 — 131, 2022 — 57, 2023 — 11. Когорти 2020 року — це 75% клієнтської бази, і вони дали 74% доходу 2023 року. Зростання тримається на старих клієнтах.
A18: 2023 Q1 | B18: =COUNTIF(Customers!$D$2:$D$805,$A18) | C18: =SUMIFS(Orders!$R$2:$R$10195,Orders!$W$2:$W$10195,$A18,Orders!$X$2:$X$10195,C$5) | D18: =SUMIFS(Orders!$R$2:$R$10195,Orders!$W$2:$W$10195,$A18,Orders!$X$2:$X$10195,D$5) | E18: =SUMIFS(Orders!$R$2:$R$10195,Orders!$W$2:$W$10195,$A18,Orders!$X$2:$X$10195,E$5) | F18: =SUMIFS(Orders!$R$2:$R$10195,Orders!$W$2:$W$10195,$A18,Orders!$X$2:$X$10195,F$5) | G18: =SUM(C18:F18)
A19: 2023 Q2 | B19: =COUNTIF(Customers!$D$2:$D$805,$A19) | C19: =SUMIFS(Orders!$R$2:$R$10195,Orders!$W$2:$W$10195,$A19,Orders!$X$2:$X$10195,C$5) | D19: =SUMIFS(Orders!$R$2:$R$10195,Orders!$W$2:$W$10195,$A19,Orders!$X$2:$X$10195,D$5) | E19: =SUMIFS(Orders!$R$2:$R$10195,Orders!$W$2:$W$10195,$A19,Orders!$X$2:$X$10195,E$5) | F19: =SUMIFS(Orders!$R$2:$R$10195,Orders!$W$2:$W$10195,$A19,Orders!$X$2:$X$10195,F$5) | G19: =SUM(C19:F19)
A20: 2023 Q3 | B20: =COUNTIF(Customers!$D$2:$D$805,$A20) | C20: =SUMIFS(Orders!$R$2:$R$10195,Orders!$W$2:$W$10195,$A20,Orders!$X$2:$X$10195,C$5) | D20: =SUMIFS(Orders!$R$2:$R$10195,Orders!$W$2:$W$10195,$A20,Orders!$X$2:$X$10195,D$5) | E20: =SUMIFS(Orders!$R$2:$R$10195,Orders!$W$2:$W$10195,$A20,Orders!$X$2:$X$10195,E$5) | F20: =SUMIFS(Orders!$R$2:$R$10195,Orders!$W$2:$W$10195,$A20,Orders!$X$2:$X$10195,F$5) | G20: =SUM(C20:F20)
A21: 2023 Q4 | B21: =COUNTIF(Customers!$D$2:$D$805,$A21) | C21: =SUMIFS(Orders!$R$2:$R$10195,Orders!$W$2:$W$10195,$A21,Orders!$X$2:$X$10195,C$5) | D21: =SUMIFS(Orders!$R$2:$R$10195,Orders!$W$2:$W$10195,$A21,Orders!$X$2:$X$10195,D$5) | E21: =SUMIFS(Orders!$R$2:$R$10195,Orders!$W$2:$W$10195,$A21,Orders!$X$2:$X$10195,E$5) | F21: =SUMIFS(Orders!$R$2:$R$10195,Orders!$W$2:$W$10195,$A21,Orders!$X$2:$X$10195,F$5) | G21: =SUM(C21:F21) | I21: Новіші когорти стартують слабше.
A22: Разом | B22: =SUM(B6:B21) | C22: =SUM(C6:C21) | D22: =SUM(D6:D21) | E22: =SUM(E6:E21) | F22: =SUM(F6:F21) | G22: =SUM(G6:G21) | I22: LTV першого року для когорт Q1 (повний рік спостереження): 2020 Q1 — $1,177, 2021 Q1 — $1,071, 2022 Q1 — $896, 2023 Q1 — $645. Кожна наступна когорта приносить менше в рік залучення, хоча на другий-третій рік когорти 2021–2022 частково наздоганяють.
A24: 2. Кумулятивний LTV за календарними роками, $ на клієнта (теплова карта)
A25: Накопичений дохід когорти на кінець року / кількість клієнтів когорти.
A26: Когорта | B26: Клієнтів | C26: 2020 | D26: 2021 | E26: 2022 | F26: 2023 | I26: Обмеження.
A27: 2020 Q1 | B27: =COUNTIF(Customers!$D$2:$D$805,$A27) | C27: =IF(C$26<VALUE(LEFT($A27,4)),"",SUM($C6:C6)/$B27) | D27: =IF(D$26<VALUE(LEFT($A27,4)),"",SUM($C6:D6)/$B27) | E27: =IF(E$26<VALUE(LEFT($A27,4)),"",SUM($C6:E6)/$B27) | F27: =IF(F$26<VALUE(LEFT($A27,4)),"",SUM($C6:F6)/$B27) | I27: Когорти 2022 Q3, 2022 Q4, 2023 Q1, 2023 Q2, 2023 Q3, 2023 Q4 мають менше 10 клієнтів — їхній LTV нестабільний і не годиться для висновків. Когорти Q4 мають лише до трьох місяців у першому році, тому в таблиці 3 порівнювати варто когорти одного кварталу. LTV рахується за доходом (Sales) без урахування повернень і прибутковості.
A28: 2020 Q2 | B28: =COUNTIF(Customers!$D$2:$D$805,$A28) | C28: =IF(C$26<VALUE(LEFT($A28,4)),"",SUM($C7:C7)/$B28) | D28: =IF(D$26<VALUE(LEFT($A28,4)),"",SUM($C7:D7)/$B28) | E28: =IF(E$26<VALUE(LEFT($A28,4)),"",SUM($C7:E7)/$B28) | F28: =IF(F$26<VALUE(LEFT($A28,4)),"",SUM($C7:F7)/$B28)
A29: 2020 Q3 | B29: =COUNTIF(Customers!$D$2:$D$805,$A29) | C29: =IF(C$26<VALUE(LEFT($A29,4)),"",SUM($C8:C8)/$B29) | D29: =IF(D$26<VALUE(LEFT($A29,4)),"",SUM($C8:D8)/$B29) | E29: =IF(E$26<VALUE(LEFT($A29,4)),"",SUM($C8:E8)/$B29) | F29: =IF(F$26<VALUE(LEFT($A29,4)),"",SUM($C8:F8)/$B29)
A30: 2020 Q4 | B30: =COUNTIF(Customers!$D$2:$D$805,$A30) | C30: =IF(C$26<VALUE(LEFT($A30,4)),"",SUM($C9:C9)/$B30) | D30: =IF(D$26<VALUE(LEFT($A30,4)),"",SUM($C9:D9)/$B30) | E30: =IF(E$26<VALUE(LEFT($A30,4)),"",SUM($C9:E9)/$B30) | F30: =IF(F$26<VALUE(LEFT($A30,4)),"",SUM($C9:F9)/$B30)
A31: 2021 Q1 | B31: =COUNTIF(Customers!$D$2:$D$805,$A31) | C31: =IF(C$26<VALUE(LEFT($A31,4)),"",SUM($C10:C10)/$B31) | D31: =IF(D$26<VALUE(LEFT($A31,4)),"",SUM($C10:D10)/$B31) | E31: =IF(E$26<VALUE(LEFT($A31,4)),"",SUM($C10:E10)/$B31) | F31: =IF(F$26<VALUE(LEFT($A31,4)),"",SUM($C10:F10)/$B31) | I31: Рекомендації.
A32: 2021 Q2 | B32: =COUNTIF(Customers!$D$2:$D$805,$A32) | C32: =IF(C$26<VALUE(LEFT($A32,4)),"",SUM($C11:C11)/$B32) | D32: =IF(D$26<VALUE(LEFT($A32,4)),"",SUM($C11:D11)/$B32) | E32: =IF(E$26<VALUE(LEFT($A32,4)),"",SUM($C11:E11)/$B32) | F32: =IF(F$26<VALUE(LEFT($A32,4)),"",SUM($C11:F11)/$B32) | I32: Орієнтир для вартості залучення: клієнт приносить близько $808 доходу в рік залучення і близько $3,130 за чотири роки. Пріоритет — відновити залучення нових клієнтів і зберегти програми утримання, які вже дають стабільні повторні покупки.
A33: 2021 Q3 | B33: =COUNTIF(Customers!$D$2:$D$805,$A33) | C33: =IF(C$26<VALUE(LEFT($A33,4)),"",SUM($C12:C12)/$B33) | D33: =IF(D$26<VALUE(LEFT($A33,4)),"",SUM($C12:D12)/$B33) | E33: =IF(E$26<VALUE(LEFT($A33,4)),"",SUM($C12:E12)/$B33) | F33: =IF(F$26<VALUE(LEFT($A33,4)),"",SUM($C12:F12)/$B33)
A34: 2021 Q4 | B34: =COUNTIF(Customers!$D$2:$D$805,$A34) | C34: =IF(C$26<VALUE(LEFT($A34,4)),"",SUM($C13:C13)/$B34) | D34: =IF(D$26<VALUE(LEFT($A34,4)),"",SUM($C13:D13)/$B34) | E34: =IF(E$26<VALUE(LEFT($A34,4)),"",SUM($C13:E13)/$B34) | F34: =IF(F$26<VALUE(LEFT($A34,4)),"",SUM($C13:F13)/$B34)
A35: 2022 Q1 | B35: =COUNTIF(Customers!$D$2:$D$805,$A35) | C35: =IF(C$26<VALUE(LEFT($A35,4)),"",SUM($C14:C14)/$B35) | D35: =IF(D$26<VALUE(LEFT($A35,4)),"",SUM($C14:D14)/$B35) | E35: =IF(E$26<VALUE(LEFT($A35,4)),"",SUM($C14:E14)/$B35) | F35: =IF(F$26<VALUE(LEFT($A35,4)),"",SUM($C14:F14)/$B35)
A36: 2022 Q2 | B36: =COUNTIF(Customers!$D$2:$D$805,$A36) | C36: =IF(C$26<VALUE(LEFT($A36,4)),"",SUM($C15:C15)/$B36) | D36: =IF(D$26<VALUE(LEFT($A36,4)),"",SUM($C15:D15)/$B36) | E36: =IF(E$26<VALUE(LEFT($A36,4)),"",SUM($C15:E15)/$B36) | F36: =IF(F$26<VALUE(LEFT($A36,4)),"",SUM($C15:F15)/$B36)
A37: 2022 Q3 | B37: =COUNTIF(Customers!$D$2:$D$805,$A37) | C37: =IF(C$26<VALUE(LEFT($A37,4)),"",SUM($C16:C16)/$B37) | D37: =IF(D$26<VALUE(LEFT($A37,4)),"",SUM($C16:D16)/$B37) | E37: =IF(E$26<VALUE(LEFT($A37,4)),"",SUM($C16:E16)/$B37) | F37: =IF(F$26<VALUE(LEFT($A37,4)),"",SUM($C16:F16)/$B37)
A38: 2022 Q4 | B38: =COUNTIF(Customers!$D$2:$D$805,$A38) | C38: =IF(C$26<VALUE(LEFT($A38,4)),"",SUM($C17:C17)/$B38) | D38: =IF(D$26<VALUE(LEFT($A38,4)),"",SUM($C17:D17)/$B38) | E38: =IF(E$26<VALUE(LEFT($A38,4)),"",SUM($C17:E17)/$B38) | F38: =IF(F$26<VALUE(LEFT($A38,4)),"",SUM($C17:F17)/$B38)
A39: 2023 Q1 | B39: =COUNTIF(Customers!$D$2:$D$805,$A39) | C39: =IF(C$26<VALUE(LEFT($A39,4)),"",SUM($C18:C18)/$B39) | D39: =IF(D$26<VALUE(LEFT($A39,4)),"",SUM($C18:D18)/$B39) | E39: =IF(E$26<VALUE(LEFT($A39,4)),"",SUM($C18:E18)/$B39) | F39: =IF(F$26<VALUE(LEFT($A39,4)),"",SUM($C18:F18)/$B39)
A40: 2023 Q2 | B40: =COUNTIF(Customers!$D$2:$D$805,$A40) | C40: =IF(C$26<VALUE(LEFT($A40,4)),"",SUM($C19:C19)/$B40) | D40: =IF(D$26<VALUE(LEFT($A40,4)),"",SUM($C19:D19)/$B40) | E40: =IF(E$26<VALUE(LEFT($A40,4)),"",SUM($C19:E19)/$B40) | F40: =IF(F$26<VALUE(LEFT($A40,4)),"",SUM($C19:F19)/$B40)
A41: 2023 Q3 | B41: =COUNTIF(Customers!$D$2:$D$805,$A41) | C41: =IF(C$26<VALUE(LEFT($A41,4)),"",SUM($C20:C20)/$B41) | D41: =IF(D$26<VALUE(LEFT($A41,4)),"",SUM($C20:D20)/$B41) | E41: =IF(E$26<VALUE(LEFT($A41,4)),"",SUM($C20:E20)/$B41) | F41: =IF(F$26<VALUE(LEFT($A41,4)),"",SUM($C20:F20)/$B41)
A42: 2023 Q4 | B42: =COUNTIF(Customers!$D$2:$D$805,$A42) | C42: =IF(C$26<VALUE(LEFT($A42,4)),"",SUM($C21:C21)/$B42) | D42: =IF(D$26<VALUE(LEFT($A42,4)),"",SUM($C21:D21)/$B42) | E42: =IF(E$26<VALUE(LEFT($A42,4)),"",SUM($C21:E21)/$B42) | F42: =IF(F$26<VALUE(LEFT($A42,4)),"",SUM($C21:F21)/$B42)
...

Sheet Customers
A1: Customer ID | B1: Customer Name | C1: Перша покупка | D1: Когорта (квартал залучення) | E1: Рік залучення
A2: AA-10315 | B2: Alex Avila | C2: =MINIFS(Orders!$C$2:$C$10195,Orders!$F$2:$F$10195,A2) | D2: =YEAR(C2)&" Q"&ROUNDUP(MONTH(C2)/3,0) | E2: =YEAR(C2)
A3: AA-10375 | B3: Allen Armold | C3: =MINIFS(Orders!$C$2:$C$10195,Orders!$F$2:$F$10195,A3) | D3: =YEAR(C3)&" Q"&ROUNDUP(MONTH(C3)/3,0) | E3: =YEAR(C3)
A4: AA-10480 | B4: Andrew Allen | C4: =MINIFS(Orders!$C$2:$C$10195,Orders!$F$2:$F$10195,A4) | D4: =YEAR(C4)&" Q"&ROUNDUP(MONTH(C4)/3,0) | E4: =YEAR(C4)
A5: AA-10645 | B5: Anna Andreadi | C5: =MINIFS(Orders!$C$2:$C$10195,Orders!$F$2:$F$10195,A5) | D5: =YEAR(C5)&" Q"&ROUNDUP(MONTH(C5)/3,0) | E5: =YEAR(C5)
A6: AB-10015 | B6: Aaron Bergman | C6: =MINIFS(Orders!$C$2:$C$10195,Orders!$F$2:$F$10195,A6) | D6: =YEAR(C6)&" Q"&ROUNDUP(MONTH(C6)/3,0) | E6: =YEAR(C6)
A7: AB-10060 | B7: Adam Bellavance | C7: =MINIFS(Orders!$C$2:$C$10195,Orders!$F$2:$F$10195,A7) | D7: =YEAR(C7)&" Q"&ROUNDUP(MONTH(C7)/3,0) | E7: =YEAR(C7)
A8: AB-10105 | B8: Adrian Barton | C8: =MINIFS(Orders!$C$2:$C$10195,Orders!$F$2:$F$10195,A8) | D8: =YEAR(C8)&" Q"&ROUNDUP(MONTH(C8)/3,0) | E8: =YEAR(C8)
A9: AB-10150 | B9: Aimee Bixby | C9: =MINIFS(Orders!$C$2:$C$10195,Orders!$F$2:$F$10195,A9) | D9: =YEAR(C9)&" Q"&ROUNDUP(MONTH(C9)/3,0) | E9: =YEAR(C9)
A10: AB-10165 | B10: Alan Barnes | C10: =MINIFS(Orders!$C$2:$C$10195,Orders!$F$2:$F$10195,A10) | D10: =YEAR(C10)&" Q"&ROUNDUP(MONTH(C10)/3,0) | E10: =YEAR(C10)
A11: AB-10255 | B11: Alejandro Ballentine | C11: =MINIFS(Orders!$C$2:$C$10195,Orders!$F$2:$F$10195,A11) | D11: =YEAR(C11)&" Q"&ROUNDUP(MONTH(C11)/3,0) | E11: =YEAR(C11)
A12: AB-10600 | B12: Ann Blume | C12: =MINIFS(Orders!$C$2:$C$10195,Orders!$F$2:$F$10195,A12) | D12: =YEAR(C12)&" Q"&ROUNDUP(MONTH(C12)/3,0) | E12: =YEAR(C12)
A13: AC-10420 | B13: Alyssa Crouse | C13: =MINIFS(Orders!$C$2:$C$10195,Orders!$F$2:$F$10195,A13) | D13: =YEAR(C13)&" Q"&ROUNDUP(MONTH(C13)/3,0) | E13: =YEAR(C13)
... A805: ZD-21925 | B805: Zuschuss Donatelli | C805: =MINIFS(Orders!$C$2:$C$10195,Orders!$F$2:$F$10195,A805) | D805: =YEAR(C805)&" Q"&ROUNDUP(MONTH(C805)/3,0) | E805: =YEAR(C805)

Sheet Orders
A1: Row ID | B1: Order ID | C1: Order Date | D1: Ship Date | E1: Ship Mode | F1: Customer ID | G1: Customer Name | H1: Segment | I1: Country/Region | J1: City | K1: State/Province | L1: Postal Code | M1: Region | N1: Product ID | O1: Category | P1: Sub-Category | Q1: Product Name | R1: Sales | S1: Quantity | T1: Discount | U1: Profit | V1: Перша покупка | W1: Когорта | X1: Рік замовлення | Y1: Рік життя
A2: 1 | B2: US-2020-103800 | C2: 43833 | D2: 43837 | E2: Standard Class | F2: DP-13000 | G2: Darren Powers | H2: Consumer | I2: United States | J2: Houston | K2: Texas | L2: 77095 | M2: Central | N2: OFF-PA-10000174 | O2: Office Supplies | P2: Paper | Q2: Message Book, Wirebound, Four 5 1/2" X 4" Forms/Pg., 200 Dupl. Sets/Book | R2: 16.448 | S2: 2 | T2: 0.2 | U2: 5.5512 | V2: =INDEX(Customers!$C$2:$C$805,MATCH(F2,Customers!$A$2:$A$805,0)) | W2: =INDEX(Customers!$D$2:$D$805,MATCH(F2,Customers!$A$2:$A$805,0)) | X2: =YEAR(C2) | Y2: =X2-YEAR(V2)+1
A3: 2 | B3: US-2020-112326 | C3: 43834 | D3: 43838 | E3: Standard Class | F3: PO-19195 | G3: Phillina Ober | H3: Home Office | I3: United States | J3: Naperville | K3: Illinois | L3: 60540 | M3: Central | N3: OFF-BI-10004094 | O3: Office Supplies | P3: Binders | Q3: GBC Standard Plastic Binding Systems Combs | R3: 3.54 | S3: 2 | T3: 0.8 | U3: -5.487 | V3: =INDEX(Customers!$C$2:$C$805,MATCH(F3,Customers!$A$2:$A$805,0)) | W3: =INDEX(Customers!$D$2:$D$805,MATCH(F3,Customers!$A$2:$A$805,0)) | X3: =YEAR(C3) | Y3: =X3-YEAR(V3)+1
A4: 3 | B4: US-2020-112326 | C4: 43834 | D4: 43838 | E4: Standard Class | F4: PO-19195 | G4: Phillina Ober | H4: Home Office | I4: United States | J4: Naperville | K4: Illinois | L4: 60540 | M4: Central | N4: OFF-LA-10003223 | O4: Office Supplies | P4: Labels | Q4: Avery 508 | R4: 11.784 | S4: 3 | T4: 0.2 | U4: 4.2717 | V4: =INDEX(Customers!$C$2:$C$805,MATCH(F4,Customers!$A$2:$A$805,0)) | W4: =INDEX(Customers!$D$2:$D$805,MATCH(F4,Customers!$A$2:$A$805,0)) | X4: =YEAR(C4) | Y4: =X4-YEAR(V4)+1
A5: 4 | B5: US-2020-112326 | C5: 43834 | D5: 43838 | E5: Standard Class | F5: PO-19195 | G5: Phillina Ober | H5: Home Office | I5: United States | J5: Naperville | K5: Illinois | L5: 60540 | M5: Central | N5: OFF-ST-10002743 | O5: Office Supplies | P5: Storage | Q5: SAFCO Boltless Steel Shelving | R5: 272.736 | S5: 3 | T5: 0.2 | U5: -64.7748 | V5: =INDEX(Customers!$C$2:$C$805,MATCH(F5,Customers!$A$2:$A$805,0)) | W5: =INDEX(Customers!$D$2:$D$805,MATCH(F5,Customers!$A$2:$A$805,0)) | X5: =YEAR(C5) | Y5: =X5-YEAR(V5)+1
A6: 5 | B6: US-2020-141817 | C6: 43835 | D6: 43842 | E6: Standard Class | F6: MB-18085 | G6: Mick Brown | H6: Consumer | I6: United States | J6: Philadelphia | K6: Pennsylvania | L6: 19143 | M6: East | N6: OFF-AR-10003478 | O6: Office Supplies | P6: Art | Q6: Avery Hi-Liter EverBold Pen Style Fluorescent Highlighters, 4/Pack | R6: 19.536 | S6: 3 | T6: 0.2 | U6: 4.884 | V6: =INDEX(Customers!$C$2:$C$805,MATCH(F6,Customers!$A$2:$A$805,0)) | W6: =INDEX(Customers!$D$2:$D$805,MATCH(F6,Customers!$A$2:$A$805,0)) | X6: =YEAR(C6) | Y6: =X6-YEAR(V6)+1
A7: 6 | B7: US-2020-167199 | C7: 43836 | D7: 43840 | E7: Standard Class | F7: ME-17320 | G7: Maria Etezadi | H7: Home Office | I7: United States | J7: Henderson | K7: Kentucky | L7: 42420 | M7: South | N7: FUR-CH-10004063 | O7: Furniture | P7: Chairs | Q7: Global Deluxe High-Back Manager's Chair | R7: 2573.82 | S7: 9 | T7: 0 | U7: 746.4078 | V7: =INDEX(Customers!$C$2:$C$805,MATCH(F7,Customers!$A$2:$A$805,0)) | W7: =INDEX(Customers!$D$2:$D$805,MATCH(F7,Customers!$A$2:$A$805,0)) | X7: =YEAR(C7) | Y7: =X7-YEAR(V7)+1
A8: 7 | B8: US-2020-167199 | C8: 43836 | D8: 43840 | E8: Standard Class | F8: ME-17320 | G8: Maria Etezadi | H8: Home Office | I8: United States | J8: Henderson | K8: Kentucky | L8: 42420 | M8: South | N8: OFF-AR-10001662 | O8: Office Supplies | P8: Art | Q8: Rogers Handheld Barrel Pencil Sharpener | R8: 5.48 | S8: 2 | T8: 0 | U8: 1.4796 | V8: =INDEX(Customers!$C$2:$C$805,MATCH(F8,Customers!$A$2:$A$805,0)) | W8: =INDEX(Customers!$D$2:$D$805,MATCH(F8,Customers!$A$2:$A$805,0)) | X8: =YEAR(C8) | Y8: =X8-YEAR(V8)+1
A9: 8 | B9: US-2020-106054 | C9: 43836 | D9: 43837 | E9: First Class | F9: JO-15145 | G9: Jack O'Briant | H9: Corporate | I9: United States | J9: Athens | K9: Georgia | L9: 30605 | M9: South | N9: OFF-AR-10002399 | O9: Office Supplies | P9: Art | Q9: Dixon Prang Watercolor Pencils, 10-Color Set with Brush | R9: 12.78 | S9: 3 | T9: 0 | U9: 5.2398 | V9: =INDEX(Customers!$C$2:$C$805,MATCH(F9,Customers!$A$2:$A$805,0)) | W9: =INDEX(Customers!$D$2:$D$805,MATCH(F9,Customers!$A$2:$A$805,0)) | X9: =YEAR(C9) | Y9: =X9-YEAR(V9)+1
A10: 9 | B10: US-2020-167199 | C10: 43836 | D10: 43840 | E10: Standard Class | F10: ME-17320 | G10: Maria Etezadi | H10: Home Office | I10: United States | J10: Henderson | K10: Kentucky | L10: 42420 | M10: South | N10: OFF-BI-10004632 | O10: Office Supplies | P10: Binders | Q10: Ibico Hi-Tech Manual Binding System | R10: 609.98 | S10: 2 | T10: 0 | U10: 274.491 | V10: =INDEX(Customers!$C$2:$C$805,MATCH(F10,Customers!$A$2:$A$805,0)) | W10: =INDEX(Customers!$D$2:$D$805,MATCH(F10,Customers!$A$2:$A$805,0)) | X10: =YEAR(C10) | Y10: =X10-YEAR(V10)+1
A11: 10 | B11: US-2020-167199 | C11: 43836 | D11: 43840 | E11: Standard Class | F11: ME-17320 | G11: Maria Etezadi | H11: Home Office | I11: United States | J11: Henderson | K11: Kentucky | L11: 42420 | M11: South | N11: OFF-FA-10001883 | O11: Office Supplies | P11: Fasteners | Q11: Alliance Super-Size Bands, Assorted Sizes | R11: 31.12 | S11: 4 | T11: 0 | U11: 0.3112 | V11: =INDEX(Customers!$C$2:$C$805,MATCH(F11,Customers!$A$2:$A$805,0)) | W11: =INDEX(Customers!$D$2:$D$805,MATCH(F11,Customers!$A$2:$A$805,0)) | X11: =YEAR(C11) | Y11: =X11-YEAR(V11)+1
A12: 11 | B12: US-2020-167199 | C12: 43836 | D12: 43840 | E12: Standard Class | F12: ME-17320 | G12: Maria Etezadi | H12: Home Office | I12: United States | J12: Henderson | K12: Kentucky | L12: 42420 | M12: South | N12: OFF-PA-10000955 | O12: Office Supplies | P12: Paper | Q12: Southworth 25% Cotton Granite Paper & Envelopes | R12: 6.54 | S12: 1 | T12: 0 | U12: 3.0084 | V12: =INDEX(Customers!$C$2:$C$805,MATCH(F12,Customers!$A$2:$A$805,0)) | W12: =INDEX(Customers!$D$2:$D$805,MATCH(F12,Customers!$A$2:$A$805,0)) | X12: =YEAR(C12) | Y12: =X12-YEAR(V12)+1
A13: 12 | B13: US-2020-130813 | C13: 43836 | D13: 43838 | E13: Second Class | F13: LS-17230 | G13: Lycoris Saunders | H13: Consumer | I13: United States | J13: Los Angeles | K13: California | L13: 90049 | M13: West | N13: OFF-PA-10002005 | O13: Office Supplies | P13: Paper | Q13: Xerox 225 | R13: 19.44 | S13: 3 | T13: 0 | U13: 9.3312 | V13: =INDEX(Customers!$C$2:$C$805,MATCH(F13,Customers!$A$2:$A$805,0)) | W13: =INDEX(Customers!$D$2:$D$805,MATCH(F13,Customers!$A$2:$A$805,0)) | X13: =YEAR(C13) | Y13: =X13-YEAR(V13)+1
... A10195: 10194 | B10195: CA-2023-143500 | C10195: 45290 | D10195: 45294 | E10195: Standard Class | F10195: HO-15230 | G10195: Harry Olson | H10195: Consumer | I10195: Canada | J10195: Charlottetown | K10195: Prince Edward Island | L10195: C0A | M10195: East | N10195: OFF-BI-10004040 | O10195: Office Supplies | P10195: Binders | Q10195: Wilson Jones Impact Binders | R10195: 3.024 | S10195: 3 | T10195: 0.2 | U10195: -0.6048 | V10195: =INDEX(Customers!$C$2:$C$805,MATCH(F10195,Customers!$A$2:$A$805,0)) | W10195: =INDEX(Customers!$D$2:$D$805,MATCH(F10195,Customers!$A$2:$A$805,0)) | X10195: =YEAR(C10195) | Y10195: =X10195-YEAR(V10195)+1

Sheet People
A1: Regional Manager | B1: Region
A2: Sadie Pawthorne | B2: West
A3: Chuck Magee | B3: East
A4: Roxanne Rodriguez | B4: Central
A5: Fred Suzuki | B5: South

Sheet Returns
A1: Returned | B1: Order ID
A2: Yes | B2: US-2020-100762
A3: Yes | B3: US-2020-100762
A4: Yes | B4: US-2020-100762
A5: Yes | B5: US-2020-100762
A6: Yes | B6: US-2020-100867
A7: Yes | B7: US-2020-102652
A8: Yes | B8: US-2020-102652
A9: Yes | B9: US-2020-102652
A10: Yes | B10: US-2020-102652
A11: Yes | B11: US-2020-103373
A12: Yes | B12: US-2020-103744
... A801: Yes | B801: US-2023-155999
